Workbook

Sheet Overview
A1: POAI at the Goa AI Tech Conclave 2026: venue and technical requirements
A2: 22–23 October 2026 · Prepared by POAI for the event management team · POAI contact: Karn Malhotra, +91 98455 22281
A3: How to read this file: Overview = what each initiative is · Spaces = the stalls and rooms needed · Requirements = every item, with quantity and who provides it · Totals = counts by item type · Open questions = what still needs confirming.
A4: Yellow cells are POAI's estimates or still to be confirmed. Event team: please use the 'Event team response' column on the Requirements sheet.
A6: # | B6: Initiative | C6: Partner / owner | D6: What it is | E6: Purpose | F6: Where at the venue | G6: When | H6: Key needs (detail on Requirements sheet)
A7: 1 | B7: Goa 2037 AI Challenge (inclusivity focus) | C7: Curiouswala Studio (Hasan Shahrukh) with Aniket; POAI as community partner | D7: A two-day AI challenge for college students across Goa, centred on inclusivity. Teams use AI to tell untold Goan stories, perform Goan art forms, or remove a real barrier for people left out (language, disability, place and cost). | E7: Build student confidence with AI and surface practical, inclusive ideas rooted in Goa. Aligns with the AI Policy's student-led innovation pillar. | F7: Build area (both days) + showcase area (23 Oct evening) | G7: Kickoff 22 Oct · building 22–23 Oct · presentations and judging 23 Oct evening | H7: Team tables and chairs, power at every table, strong Wi-Fi, a screen for the kickoff, and a showcase space with screen, PA and mics
A8: 2 | B8: Generation ReMix: mentoring, both ways | C8: The Silver Surfers Club (Dipti Varma Narain) × POAI (Karn Malhotra) | D8: An intergenerational mentoring pilot. Experienced professionals mentor students and young adults (18+) on study and career choices; the young people teach them AI and digital tools in return. | E8: Connect two generations around AI and work, and pilot a mentorship platform that continues after the Conclave. | F8: Stall B (6x3) shared with POAI + a quiet space for conversations | G8: Day 1 (22 Oct): mentor profiles on display · Day 2 (23 Oct): sign-up, matching and mentoring conversations | H8: A 6x3 stall with screen and profile display, sign-up desk, senior-friendly seating, and a separate quiet space on Day 2
A9: 3 | B9: Sentiment to Swag | C9: Harshit Agarwal | D9: A live generative artwork on a big screen that reflects how attendees feel about each session. People respond via a QR code on their phones (or a tablet); the artwork changes every 30–60 minutes and past artworks can become swag. | E9: Give the room a visible, shared voice and create Goan-made artwork from the Conclave. | F9: High-footfall spot: in Stall B or near the main hall exit (to confirm) | G9: Both days, all day | H9: One large TV on a stand, HDMI, stable internet, power for TV and laptop
A10: 4 | B10: Digital Delight with Susegad | C10: Sarat Gnanamgari (Asymmetrica AI) | D10: Every registrant gets a free digital Goa postcard with their name and a Conclave stamp, built on Susegad, an open-source Goan design library. | E10: A small Goan moment for every attendee, and a shareable asset that spreads the Conclave online. | F10: Online (registration flow) + optional screen near registration | G10: Before the event (from registration) and during it | H10: A link added to the registration confirmation page or email; optional screen near registration
A11: 5 | B11: The AI Guy on Radio Mandovi 88.4 FM | C11: Karn Malhotra (host) with Radio Mandovi 88.4 FM; booth setup with Dr. Ashwin | D11: A live broadcast booth at the Conclave: speaker interviews on air, then follow-up episodes after the event. The weekly show also runs on Spotify. | E11: AI literacy for every citizen, reaching people who are not online, and lasting coverage of the Conclave. | F11: Stall A (3x3), or a quiet room in a prominent spot if the stall cannot be made quiet enough | G11: Both days | H11: A semi-enclosed 3x3 stall with sound dampening, table and chairs, wired internet, power and 'On Air' branding

Sheet Spaces
A1: Spaces needed
A2: Three 3x3 stall units in total: one on its own for Radio Mandovi, and two combined into a 6x3 stall for POAI and Generation ReMix. Plus a quiet space for mentoring, and a backup recording room if needed.
A4: Space | B4: Size | C4: Stall units (3x3) | D4: Used by | E4: Days needed | F4: Must-have features | G4: Location preference | H4: Event team response
A5: Stall A: Radio Mandovi broadcast booth | B5: 3m x 3m | C5: 1 | D5: The AI Guy on Radio Mandovi 88.4 FM | E5: 22 and 23 Oct | F5: Semi-enclosed (back and side walls); sound dampening (acoustic panels or heavy drapes, carpet); wired internet; 'On Air' sign | G5: Prominent and visible, so people can see recordings happening, but away from the loudest areas (stage, music, food)
A6: Stall B: POAI + Generation ReMix | B6: 6m x 3m (two 3x3 units combined) | C6: 2 | D6: Generation ReMix (Silver Surfers Club × POAI); Sentiment to Swag screen if placed here; POAI community welcome | E6: 22 and 23 Oct | F6: Open front; mentor profile display; screen; sign-up desk; seating with backrests for senior mentors | G6: High footfall, step-free (wheelchair accessible), close to the quiet space
A7: Quiet space: mentoring conversations | B7: Room or enclosed area for about 4 conversation tables (12–16 people) | C7: 0 | D7: Generation ReMix mentors and students | E7: 23 Oct (full day); 22 Oct for a short mentor briefing if available | F7: Low noise, enclosed or partitioned; step-free access; near restrooms; drinking water | G7: Next to or near Stall B
A8: Backup: quiet recording room (only if Stall A is not quiet enough) | B8: Small room for 4 people | C8: 0 | D8: The AI Guy on Radio Mandovi 88.4 FM | E8: 22 and 23 Oct | F8: Quiet; wired internet; power; visible from outside (glass door/window) or clear 'Recording in progress' signage | G8: Prominent area, so attendees know recordings are happening
A9: Goa 2037 build area | B9: Space for about 15 team tables (est.) | C9: 0 | D9: Goa 2037 AI Challenge teams and mentors | E9: 22 and 23 Oct | F9: Team tables and chairs; power at every table; strong Wi-Fi for about 60 laptops; one screen for the kickoff | G9: Indoors, close to the showcase area
A10: Goa 2037 showcase area | B10: Stage or hall for about 80 people (est.) | C10: 0 | D10: Goa 2037 presentations, performances and accessibility demos; jury | E10: 23 Oct evening | F10: Screen or projector; PA with mics; clear floor space for performances; demo tables; jury table; step-free access and reserved accessible seating | G10: One of the halls, or a stage area that can be used in the evening
B11: Total stall units | C11: =SUM(C5:C10) -> 3

Sheet Requirements
A1: Itemised requirements
A2: Priority: Must = needed for the initiative to run · Optional = nice to have. Provided by: who supplies the item. Yellow = estimate or to confirm.
A4: # | B4: Initiative | C4: Space | D4: Category | E4: Item | F4: Specification | G4: Qty | H4: Item type (for totals) | I4: When needed | J4: Priority | K4: Provided by | L4: Notes | M4: Event team response
A5: 1 | B5: Radio Mandovi | C5: Stall A | D5: Space | E5: 3x3 stall | F5: Semi-enclosed shell stall, 3m x 3m, back and side walls | G5: 1 | H5: Stall unit (3x3) | I5: 22–23 Oct | J5: Must | K5: Event team
A6: 2 | B6: Radio Mandovi | C6: Stall A | D6: Acoustics | E6: Sound dampening | F6: Acoustic panels or heavy drapes on the walls, carpet or rug on the floor | G6: 1 | H6: Other | I6: 22–23 Oct | J6: Must | K6: Event team | L6: If the stall cannot be made quiet enough, use the backup recording room instead
A7: 3 | B7: Radio Mandovi | C7: Stall A | D7: Furniture | E7: Broadcast table | F7: Table about 1.5m x 0.75m, with a cloth | G7: 1 | H7: Table | I7: 22–23 Oct | J7: Must | K7: Event team
A8: 4 | B8: Radio Mandovi | C8: Stall A | D8: Furniture | E8: Chairs | F8: Chairs with backrests: 1 host + up to 3 guests | G8: 4 | H8: Chair | I8: 22–23 Oct | J8: Must | K8: Event team
A9: 5 | B9: Radio Mandovi | C9: Stall A | D9: Branding | E9: Backdrop and 'On Air' sign | F9: Backdrop with Radio Mandovi 88.4 FM, The AI Guy and POAI logos; an 'On Air' light or sign | G9: 1 | H9: Branding | I9: 22–23 Oct | J9: Must | K9: Event team (print); POAI (artwork) | L9: Artwork from POAI
A10: 6 | B10: Radio Mandovi | C10: Stall A | D10: Screen | E10: Info screen | F10: 32–43 inch TV on a stand showing 'Live now / Up next' guests | G10: 1 | H10: Screen 32–43 inch | I10: 22–23 Oct | J10: Optional | K10: Event team
A11: 7 | B11: Radio Mandovi | C11: Stall A | D11: Power | E11: Power sockets | F11: Sockets for audio mixer, laptop and mics, plus 1 extension board | G11: 4 | H11: Power socket | I11: 22–23 Oct | J11: Must | K11: Event team
A12: 8 | B12: Radio Mandovi | C12: Stall A | D12: Internet | E12: Wired internet | F12: Dedicated wired LAN for live broadcast/streaming, at least 10 Mbps upload | G12: 1 | H12: Internet connection | I12: 22–23 Oct | J12: Must | K12: Event team
A13: 9 | B13: Radio Mandovi | C13: Stall A | D13: Audio | E13: Broadcast audio kit | F13: Microphones, headphones and mixer | G13: 1 | H13: Other | I13: 22–23 Oct | J13: Must | K13: Radio Mandovi | L13: To confirm with Radio Mandovi what they bring
A14: 10 | B14: Radio Mandovi | C14: Backup recording room | D14: Space | E14: Quiet recording room | F14: Small room for 4 people, in a prominent spot, visible from outside or with clear 'Recording in progress' signage | G14: 1 | H14: Room | I14: 22–23 Oct | J14: Optional | K14: Event team | L14: Only needed if Stall A is not quiet enough
A15: 11 | B15: Generation ReMix | C15: Stall B | D15: Space | E15: 6x3 stall | F15: Two 3x3 stall units combined into one 6m x 3m stall, open front, step-free | G15: 2 | H15: Stall unit (3x3) | I15: 22–23 Oct | J15: Must | K15: Event team | L15: Shared by Generation ReMix and POAI
A16: 12 | B16: Generation ReMix | C16: Stall B | D16: Branding | E16: Stall backdrop and fascia | F16: Backdrop and fascia: 'Generation ReMix · The Silver Surfers Club × POAI' | G16: 1 | H16: Branding | I16: 22–23 Oct | J16: Must | K16: Event team (print); POAI (artwork) | L16: Artwork from POAI
A17: 13 | B17: Generation ReMix | C17: Stall B | D17: Screen | E17: Mentor profile screen | F17: 55 inch TV on a floor stand, HDMI input, looping mentor profiles and POAI content | G17: 1 | H17: Screen 55 inch | I17: 22–23 Oct | J17: Must | K17: Event team | L17: Content from POAI on a laptop or USB
A18: 14 | B18: Generation ReMix | C18: Stall B | D18: Display | E18: Mentor profile wall | F18: Printed mentor profile panel or standees, so students can see who is taking part | G18: 1 | H18: Branding | I18: 22–23 Oct | J18: Must | K18: Event team (print); Silver Surfers Club (profiles) | L18: Number of profiles depends on mentors confirmed
A19: 15 | B19: Generation ReMix | C19: Stall B | D19: Display | E19: QR sign-up standees | F19: A4 table-top standees with the sign-up QR code | G19: 3 | H19: Branding | I19: 22–23 Oct | J19: Must | K19: Event team (print); POAI (artwork)
A20: 16 | B20: Generation ReMix | C20: Stall B | D20: Furniture | E20: Sign-up and matching desk | F20: Table with cloth | G20: 1 | H20: Table | I20: 22–23 Oct | J20: Must | K20: Event team
A21: 17 | B21: Generation ReMix | C21: Stall B | D21: Furniture | E21: Desk chairs | F21: Chairs for the sign-up desk | G21: 2 | H21: Chair | I21: 22–23 Oct | J21: Must | K21: Event team
A22: 18 | B22: Generation ReMix | C22: Stall B | D22: Furniture | E22: Seating for mentors and visitors | F22: Chairs with backrests (armrests preferred) for senior mentors | G22: 6 | H22: Chair | I22: 22–23 Oct | J22: Must | K22: Event team
A23: 19 | B23: Generation ReMix | C23: Stall B | D23: Power | E23: Power sockets | F23: For the TV, a laptop and phone charging, plus 1 extension board | G23: 3 | H23: Power socket | I23: 22–23 Oct | J23: Must | K23: Event team
A24: 20 | B24: Generation ReMix | C24: Stall B | D24: Internet | E24: Wi-Fi access | F24: Wi-Fi for the sign-up laptop/tablet | G24: 1 | H24: Internet connection | I24: 22–23 Oct | J24: Must | K24: Event team
A25: 21 | B25: Generation ReMix | C25: Stall B | D25: Equipment | E25: Sign-up laptop or tablet | F25: For student sign-ups and matching | G25: 1 | H25: Other | I25: 22–23 Oct | J25: Must | K25: POAI
A26: 22 | B26: Generation ReMix | C26: Quiet space | D26: Space | E26: Quiet mentoring room | F26: Enclosed or partitioned area for about 4 conversation tables, low noise, step-free, near restrooms | G26: 1 | H26: Room | I26: 23 Oct (full day) | J26: Must | K26: Event team | L26: Mentoring is one-to-one, or small groups for 18–20 year olds
A27: 23 | B27: Generation ReMix | C27: Quiet space | D27: Furniture | E27: Conversation tables | F27: Small round or square tables | G27: 4 | H27: Table | I27: 23 Oct | J27: Must | K27: Event team
A28: 24 | B28: Generation ReMix | C28: Quiet space | D28: Furniture | E28: Chairs | F28: Chairs with backrests: 3–4 per table | G28: 14 | H28: Chair | I28: 23 Oct | J28: Must | K28: Event team
A29: 25 | B29: Generation ReMix | C29: Quiet space | D29: Signage | E29: Quiet signage | F29: 'Generation ReMix mentoring in progress, quiet please' | G29: 2 | H29: Branding | I29: 23 Oct | J29: Must | K29: Event team (print); POAI (artwork)
A30: 26 | B30: Generation ReMix | C30: Quiet space | D30: Hospitality | E30: Drinking water | F30: Water for senior mentors and students through the day | G30: 1 | H30: Other | I30: 23 Oct | J30: Must | K30: Event team
A31: 27 | B31: Sentiment to Swag | C31: Stall B or near main hall exit | D31: Screen | E31: Artwork screen | F31: 65 inch TV (55 inch minimum) on a floor stand, landscape, HDMI input | G31: 1 | H31: Screen 65 inch | I31: 22–23 Oct | J31: Must | K31: Event team | L31: Shows the live artwork with a QR code at the bottom
A32: 28 | B32: Sentiment to Swag | C32: Stall B or near main hall exit | D32: Cabling | E32: HDMI cable | F32: HDMI cable, 3m, MacBook to TV | G32: 1 | H32: Other | I32: 22–23 Oct | J32: Must | K32: Event team
A33: 29 | B33: Sentiment to Swag | C33: Stall B or near main hall exit | D33: Equipment | E33: MacBook | F33: Runs the artwork web app, connected to the TV | G33: 1 | H33: Other | I33: 22–23 Oct | J33: Must | K33: Harshit Agarwal
A34: 30 | B34: Sentiment to Swag | C34: Stall B or near main hall exit | D34: Equipment | E34: Response tablet on stand | F34: Tablet on a floor stand for attendees who prefer not to use their phone | G34: 1 | H34: Other | I34: 22–23 Oct | J34: Optional | K34: Harshit Agarwal / POAI | L34: Most responses come via the QR code on phones
A35: 31 | B35: Sentiment to Swag | C35: Stall B or near main hall exit | D35: Internet | E35: Stable internet | F35: Wired LAN preferred, or dedicated Wi-Fi, at least 20 Mbps | G35: 1 | H35: Internet connection | I35: 22–23 Oct | J35: Must | K35: Event team
A36: 32 | B36: Sentiment to Swag | C36: Stall B or near main hall exit | D36: Power | E36: Power sockets | F36: For the TV, MacBook and tablet | G36: 3 | H36: Power socket | I36: 22–23 Oct | J36: Must | K36: Event team
A37: 33 | B37: Susegad | C37: Online | D37: Registration | E37: Postcard link in registration flow | F37: Add a 'Claim your Goa postcard' link to the registration confirmation page or email | G37: 1 | H37: Other | I37: Before registration opens to the public, or as soon as possible | J37: Must | K37: Registration platform team | L37: POAI shares the link; personalised link with first name if possible
A38: 34 | B38: Susegad | C38: Near registration | D38: Screen | E38: Postcard wall screen | F38: 43–55 inch TV on a stand near registration, showing Goa postcards | G38: 1 | H38: Screen 43–55 inch | I38: 22–23 Oct | J38: Optional | K38: Event team
A39: 35 | B39: Susegad | C39: Near registration | D39: Power | E39: Power socket | F39: For the postcard screen | G39: 1 | H39: Power socket | I39: 22–23 Oct | J39: Optional | K39: Event team
A40: 36 | B40: Goa 2037 AI Challenge | C40: Build area | D40: Furniture | E40: Team tables | F40: 6 ft tables, one per team | G40: 15 | H40: Table | I40: 22–23 Oct | J40: Must | K40: Event team | L40: Estimate: about 15 teams; confirm with Curiouswala after sign-ups close
A41: 37 | B41: Goa 2037 AI Challenge | C41: Build area | D41: Furniture | E41: Team chairs | F41: 4 chairs per team | G41: 60 | H41: Chair | I41: 22–23 Oct | J41: Must | K41: Event team | L41: Estimate, as above
...

Sheet Totals
A1: Totals by item type
A2: Calculated from the Requirements sheet. Edit quantities there, not here.
A4: Item type | B4: Must-have | C4: Including optional
A5: Stall unit (3x3) | B5: =SUMIFS(Requirements!$G$5:$G$56,Requirements!$H$5:$H$56,$A5,Requirements!$J$5:$J$56,"Must") -> 3 | C5: =SUMIFS(Requirements!$G$5:$G$56,Requirements!$H$5:$H$56,$A5) -> 3
A6: Room | B6: =SUMIFS(Requirements!$G$5:$G$56,Requirements!$H$5:$H$56,$A6,Requirements!$J$5:$J$56,"Must") -> 1 | C6: =SUMIFS(Requirements!$G$5:$G$56,Requirements!$H$5:$H$56,$A6) -> 2
A7: Screen 65 inch | B7: =SUMIFS(Requirements!$G$5:$G$56,Requirements!$H$5:$H$56,$A7,Requirements!$J$5:$J$56,"Must") -> 1 | C7: =SUMIFS(Requirements!$G$5:$G$56,Requirements!$H$5:$H$56,$A7) -> 1
A8: Screen 65–75 inch / projector | B8: =SUMIFS(Requirements!$G$5:$G$56,Requirements!$H$5:$H$56,$A8,Requirements!$J$5:$J$56,"Must") -> 2 | C8: =SUMIFS(Requirements!$G$5:$G$56,Requirements!$H$5:$H$56,$A8) -> 2
A9: Screen 55 inch | B9: =SUMIFS(Requirements!$G$5:$G$56,Requirements!$H$5:$H$56,$A9,Requirements!$J$5:$J$56,"Must") -> 1 | C9: =SUMIFS(Requirements!$G$5:$G$56,Requirements!$H$5:$H$56,$A9) -> 1
A10: Screen 43–55 inch | B10: =SUMIFS(Requirements!$G$5:$G$56,Requirements!$H$5:$H$56,$A10,Requirements!$J$5:$J$56,"Must") -> 0 | C10: =SUMIFS(Requirements!$G$5:$G$56,Requirements!$H$5:$H$56,$A10) -> 1
A11: Screen 32–43 inch | B11: =SUMIFS(Requirements!$G$5:$G$56,Requirements!$H$5:$H$56,$A11,Requirements!$J$5:$J$56,"Must") -> 0 | C11: =SUMIFS(Requirements!$G$5:$G$56,Requirements!$H$5:$H$56,$A11) -> 1
A12: Table | B12: =SUMIFS(Requirements!$G$5:$G$56,Requirements!$H$5:$H$56,$A12,Requirements!$J$5:$J$56,"Must") -> 27 | C12: =SUMIFS(Requirements!$G$5:$G$56,Requirements!$H$5:$H$56,$A12) -> 27
A13: Chair | B13: =SUMIFS(Requirements!$G$5:$G$56,Requirements!$H$5:$H$56,$A13,Requirements!$J$5:$J$56,"Must") -> 171 | C13: =SUMIFS(Requirements!$G$5:$G$56,Requirements!$H$5:$H$56,$A13) -> 171
A14: Power socket | B14: =SUMIFS(Requirements!$G$5:$G$56,Requirements!$H$5:$H$56,$A14,Requirements!$J$5:$J$56,"Must") -> 25 | C14: =SUMIFS(Requirements!$G$5:$G$56,Requirements!$H$5:$H$56,$A14) -> 26
A15: Internet connection | B15: =SUMIFS(Requirements!$G$5:$G$56,Requirements!$H$5:$H$56,$A15,Requirements!$J$5:$J$56,"Must") -> 4 | C15: =SUMIFS(Requirements!$G$5:$G$56,Requirements!$H$5:$H$56,$A15) -> 4
A16: Branding | B16: =SUMIFS(Requirements!$G$5:$G$56,Requirements!$H$5:$H$56,$A16,Requirements!$J$5:$J$56,"Must") -> 8 | C16: =SUMIFS(Requirements!$G$5:$G$56,Requirements!$H$5:$H$56,$A16) -> 8
A17: Pass | B17: =SUMIFS(Requirements!$G$5:$G$56,Requirements!$H$5:$H$56,$A17,Requirements!$J$5:$J$56,"Must") -> 0 | C17: =SUMIFS(Requirements!$G$5:$G$56,Requirements!$H$5:$H$56,$A17) -> 0
A18: All screens (any size) | B18: =SUM(B7:B11) -> 4 | C18: =SUM(C7:C11) -> 6
A20: Power socket counts include extension boards (Goa 2037 counts one 4-socket board per team table). Pass count is 0 until POAI shares numbers.

Sheet Open questions
A1: Still to confirm
A3: # | B3: Question | C3: Who answers | D3: Answer
A4: 1 | B4: Can Stall A be made quiet enough for broadcast, or do we need the backup recording room? | C4: Event team + Radio Mandovi
A5: 2 | B5: What audio equipment does Radio Mandovi bring, and what does it need from the venue? | C5: Radio Mandovi / Karn
A6: 3 | B6: Where does the Sentiment to Swag screen go: in Stall B or near the main hall exit? | C6: Event team + Harshit
A7: 4 | B7: How many Goa 2037 teams and students? (Estimates assume about 15 teams of 4.) | C7: Curiouswala (Hasan, Aniket)
A8: 5 | B8: Which hall or stage hosts the Goa 2037 showcase on the evening of 23 Oct? | C8: Event team
A9: 6 | B9: How many mentors will attend on Day 2, and for which hours? | C9: Silver Surfers Club (Dipti)
A10: 7 | B10: Is a quiet room available near Stall B on 23 Oct? | C10: Event team
A11: 8 | B11: Who runs the registration platform, and can it carry the Susegad postcard link? | C11: Event team
A12: 9 | B12: How many passes are needed for the POAI team, partners, mentors and volunteers? | C12: POAI (Karn)
A13: 10 | B13: Will setup access be available on the evening of 21 Oct? | C13: Event team
